[2024-08-08T08:05:43.961+0000] {local_task_job_runner.py:120} INFO - ::group::Pre task execution logs
[2024-08-08T08:05:43.982+0000] {taskinstance.py:2073} INFO - Dependencies all met for dep_context=non-requeueable deps ti=<TaskInstance: update_11str.update_11str scheduled__2024-08-08T04:00:00+00:00 [queued]>
[2024-08-08T08:05:43.989+0000] {taskinstance.py:2073} INFO - Dependencies all met for dep_context=requeueable deps ti=<TaskInstance: update_11str.update_11str scheduled__2024-08-08T04:00:00+00:00 [queued]>
[2024-08-08T08:05:43.989+0000] {taskinstance.py:2303} INFO - Starting attempt 2 of 2
[2024-08-08T08:05:44.001+0000] {taskinstance.py:2327} INFO - Executing <Task(PythonOperator): update_11str> on 2024-08-08 04:00:00+00:00
[2024-08-08T08:05:44.010+0000] {standard_task_runner.py:63} INFO - Started process 357 to run task
[2024-08-08T08:05:44.014+0000] {standard_task_runner.py:90} INFO - Running: ['***', 'tasks', 'run', 'update_11str', 'update_11str', 'scheduled__2024-08-08T04:00:00+00:00', '--job-id', '85', '--raw', '--subdir', 'DAGS_FOLDER/str11_batch.py', '--cfg-path', '/tmp/tmpfp72lb_c']
[2024-08-08T08:05:44.017+0000] {standard_task_runner.py:91} INFO - Job 85: Subtask update_11str
[2024-08-08T08:05:44.061+0000] {task_command.py:426} INFO - Running <TaskInstance: update_11str.update_11str scheduled__2024-08-08T04:00:00+00:00 [running]> on host b4c0c56d2c27
[2024-08-08T08:05:44.135+0000] {taskinstance.py:2644} INFO - Exporting env vars: AIRFLOW_CTX_DAG_OWNER='zzioni' AIRFLOW_CTX_DAG_ID='update_11str' AIRFLOW_CTX_TASK_ID='update_11str' AIRFLOW_CTX_EXECUTION_DATE='2024-08-08T04:00:00+00:00' AIRFLOW_CTX_TRY_NUMBER='2' AIRFLOW_CTX_DAG_RUN_ID='scheduled__2024-08-08T04:00:00+00:00'
[2024-08-08T08:05:44.136+0000] {taskinstance.py:430} INFO - ::endgroup::
[2024-08-08T08:05:44.919+0000] {taskinstance.py:441} INFO - ::group::Post task execution logs
[2024-08-08T08:05:44.920+0000] {taskinstance.py:2890} ERROR - Task failed with exception
Traceback (most recent call last):
  File "/home/airflow/.local/lib/python3.10/site-packages/airflow/models/taskinstance.py", line 465, in _execute_task
    result = _execute_callable(context=context, **execute_callable_kwargs)
  File "/home/airflow/.local/lib/python3.10/site-packages/airflow/models/taskinstance.py", line 432, in _execute_callable
    return execute_callable(context=context, **execute_callable_kwargs)
  File "/home/airflow/.local/lib/python3.10/site-packages/airflow/models/baseoperator.py", line 400, in wrapper
    return func(self, *args, **kwargs)
  File "/home/airflow/.local/lib/python3.10/site-packages/airflow/operators/python.py", line 235, in execute
    return_value = self.execute_callable()
  File "/home/airflow/.local/lib/python3.10/site-packages/airflow/operators/python.py", line 252, in execute_callable
    return self.python_callable(*self.op_args, **self.op_kwargs)
  File "/opt/airflow/dags/str11_batch.py", line 28, in update_11str
    price, prices_id, deleted = extract_price_11str()
  File "/opt/airflow/dags/utils/crawl_11str.py", line 103, in extract_price_11str
    driver = webdriver.Chrome(options=chrome_options)
  File "/home/airflow/.local/lib/python3.10/site-packages/selenium/webdriver/chrome/webdriver.py", line 45, in __init__
    super().__init__(
  File "/home/airflow/.local/lib/python3.10/site-packages/selenium/webdriver/chromium/webdriver.py", line 50, in __init__
    self.service.start()
  File "/home/airflow/.local/lib/python3.10/site-packages/selenium/webdriver/common/service.py", line 102, in start
    self.assert_process_still_running()
  File "/home/airflow/.local/lib/python3.10/site-packages/selenium/webdriver/common/service.py", line 115, in assert_process_still_running
    raise WebDriverException(f"Service {self._path} unexpectedly exited. Status code was: {return_code}")
selenium.common.exceptions.WebDriverException: Message: Service /home/airflow/.cache/selenium/chromedriver/linux64/127.0.6533.99/chromedriver unexpectedly exited. Status code was: 127

[2024-08-08T08:05:44.931+0000] {taskinstance.py:1205} INFO - Marking task as FAILED. dag_id=update_11str, task_id=update_11str, execution_date=20240808T040000, start_date=20240808T080543, end_date=20240808T080544
[2024-08-08T08:05:44.942+0000] {standard_task_runner.py:110} ERROR - Failed to execute job 85 for task update_11str (Message: Service /home/airflow/.cache/selenium/chromedriver/linux64/127.0.6533.99/chromedriver unexpectedly exited. Status code was: 127
; 357)
[2024-08-08T08:05:44.986+0000] {local_task_job_runner.py:240} INFO - Task exited with return code 1
[2024-08-08T08:05:45.008+0000] {taskinstance.py:3482} INFO - 0 downstream tasks scheduled from follow-on schedule check
[2024-08-08T08:05:45.011+0000] {local_task_job_runner.py:222} INFO - ::endgroup::
