[2024-08-08T04:51:28.367+0000] {local_task_job_runner.py:120} INFO - ::group::Pre task execution logs
[2024-08-08T04:51:28.386+0000] {taskinstance.py:2073} INFO - Dependencies all met for dep_context=non-requeueable deps ti=<TaskInstance: update_coupang.update_coupang scheduled__2024-08-08T00:00:00+00:00 [queued]>
[2024-08-08T04:51:28.393+0000] {taskinstance.py:2073} INFO - Dependencies all met for dep_context=requeueable deps ti=<TaskInstance: update_coupang.update_coupang scheduled__2024-08-08T00:00:00+00:00 [queued]>
[2024-08-08T04:51:28.393+0000] {taskinstance.py:2303} INFO - Starting attempt 3 of 3
[2024-08-08T04:51:28.404+0000] {taskinstance.py:2327} INFO - Executing <Task(PythonOperator): update_coupang> on 2024-08-08 00:00:00+00:00
[2024-08-08T04:51:28.413+0000] {standard_task_runner.py:63} INFO - Started process 1748 to run task
[2024-08-08T04:51:28.416+0000] {standard_task_runner.py:90} INFO - Running: ['***', 'tasks', 'run', 'update_coupang', 'update_coupang', 'scheduled__2024-08-08T00:00:00+00:00', '--job-id', '50', '--raw', '--subdir', 'DAGS_FOLDER/coupang_batch.py', '--cfg-path', '/tmp/tmp7am9alcl']
[2024-08-08T04:51:28.417+0000] {standard_task_runner.py:91} INFO - Job 50: Subtask update_coupang
[2024-08-08T04:51:28.458+0000] {task_command.py:426} INFO - Running <TaskInstance: update_coupang.update_coupang scheduled__2024-08-08T00:00:00+00:00 [running]> on host af5f4ca33584
[2024-08-08T04:51:28.527+0000] {taskinstance.py:2644} INFO - Exporting env vars: AIRFLOW_CTX_DAG_OWNER='zzioni' AIRFLOW_CTX_DAG_ID='update_coupang' AIRFLOW_CTX_TASK_ID='update_coupang' AIRFLOW_CTX_EXECUTION_DATE='2024-08-08T00:00:00+00:00' AIRFLOW_CTX_TRY_NUMBER='3' AIRFLOW_CTX_DAG_RUN_ID='scheduled__2024-08-08T00:00:00+00:00'
[2024-08-08T04:51:28.528+0000] {taskinstance.py:430} INFO - ::endgroup::
[2024-08-08T04:51:28.528+0000] {taskinstance.py:441} INFO - ::group::Post task execution logs
[2024-08-08T04:51:28.528+0000] {taskinstance.py:2890} ERROR - Task failed with exception
Traceback (most recent call last):
  File "/home/airflow/.local/lib/python3.10/site-packages/airflow/models/taskinstance.py", line 465, in _execute_task
    result = _execute_callable(context=context, **execute_callable_kwargs)
  File "/home/airflow/.local/lib/python3.10/site-packages/airflow/models/taskinstance.py", line 432, in _execute_callable
    return execute_callable(context=context, **execute_callable_kwargs)
  File "/home/airflow/.local/lib/python3.10/site-packages/airflow/models/baseoperator.py", line 400, in wrapper
    return func(self, *args, **kwargs)
  File "/home/airflow/.local/lib/python3.10/site-packages/airflow/operators/python.py", line 235, in execute
    return_value = self.execute_callable()
  File "/home/airflow/.local/lib/python3.10/site-packages/airflow/operators/python.py", line 252, in execute_callable
    return self.python_callable(*self.op_args, **self.op_kwargs)
  File "/opt/airflow/dags/coupang_batch.py", line 98, in coupang_info_manual
    with open('/data/jw_vol/airflow/dags/utils/mongo.yaml') as f:
FileNotFoundError: [Errno 2] No such file or directory: '/data/jw_vol/airflow/dags/utils/mongo.yaml'
[2024-08-08T04:51:28.536+0000] {taskinstance.py:1205} INFO - Marking task as FAILED. dag_id=update_coupang, task_id=update_coupang, execution_date=20240808T000000, start_date=20240808T045128, end_date=20240808T045128
[2024-08-08T04:51:28.546+0000] {standard_task_runner.py:110} ERROR - Failed to execute job 50 for task update_coupang ([Errno 2] No such file or directory: '/data/jw_vol/airflow/dags/utils/mongo.yaml'; 1748)
[2024-08-08T04:51:28.587+0000] {local_task_job_runner.py:240} INFO - Task exited with return code 1
[2024-08-08T04:51:28.624+0000] {taskinstance.py:3482} INFO - 0 downstream tasks scheduled from follow-on schedule check
[2024-08-08T04:51:28.629+0000] {local_task_job_runner.py:222} INFO - ::endgroup::
