[2024-08-07T07:37:11.308+0000] {taskinstance.py:1083} INFO - Dependencies all met for <TaskInstance: update_coupang.update_coupang scheduled__2024-08-06T08:00:00+00:00 [queued]>
[2024-08-07T07:37:11.317+0000] {taskinstance.py:1083} INFO - Dependencies all met for <TaskInstance: update_coupang.update_coupang scheduled__2024-08-06T08:00:00+00:00 [queued]>
[2024-08-07T07:37:11.317+0000] {taskinstance.py:1279} INFO - 
--------------------------------------------------------------------------------
[2024-08-07T07:37:11.317+0000] {taskinstance.py:1280} INFO - Starting attempt 1 of 1
[2024-08-07T07:37:11.317+0000] {taskinstance.py:1281} INFO - 
--------------------------------------------------------------------------------
[2024-08-07T07:37:11.331+0000] {taskinstance.py:1300} INFO - Executing <Task(PythonOperator): update_coupang> on 2024-08-06 08:00:00+00:00
[2024-08-07T07:37:11.340+0000] {standard_task_runner.py:55} INFO - Started process 32888 to run task
[2024-08-07T07:37:11.342+0000] {standard_task_runner.py:82} INFO - Running: ['***', 'tasks', 'run', 'update_coupang', 'update_coupang', 'scheduled__2024-08-06T08:00:00+00:00', '--job-id', '12', '--raw', '--subdir', 'DAGS_FOLDER/coupang_batch.py', '--cfg-path', '/tmp/tmpgt01y8g9']
[2024-08-07T07:37:11.342+0000] {standard_task_runner.py:83} INFO - Job 12: Subtask update_coupang
[2024-08-07T07:37:11.403+0000] {task_command.py:388} INFO - Running <TaskInstance: update_coupang.update_coupang scheduled__2024-08-06T08:00:00+00:00 [running]> on host df52d8e27975
[2024-08-07T07:37:11.463+0000] {taskinstance.py:1509} INFO - Exporting the following env vars:
AIRFLOW_CTX_DAG_OWNER=zzioni
AIRFLOW_CTX_DAG_ID=update_coupang
AIRFLOW_CTX_TASK_ID=update_coupang
AIRFLOW_CTX_EXECUTION_DATE=2024-08-06T08:00:00+00:00
AIRFLOW_CTX_TRY_NUMBER=1
AIRFLOW_CTX_DAG_RUN_ID=scheduled__2024-08-06T08:00:00+00:00
[2024-08-07T07:37:11.464+0000] {taskinstance.py:1768} ERROR - Task failed with exception
Traceback (most recent call last):
  File "/home/airflow/.local/lib/python3.7/site-packages/airflow/operators/python.py", line 175, in execute
    return_value = self.execute_callable()
  File "/home/airflow/.local/lib/python3.7/site-packages/airflow/operators/python.py", line 192, in execute_callable
    return self.python_callable(*self.op_args, **self.op_kwargs)
  File "/opt/airflow/dags/coupang_batch.py", line 99, in coupang_info_manual
    with open('/data/shopai/dags/hatchery-shopai-v2-model/hatchery_extract_model/utils/mongo.yaml') as f:
FileNotFoundError: [Errno 2] No such file or directory: '/data/shopai/dags/hatchery-shopai-v2-model/hatchery_extract_model/utils/mongo.yaml'
[2024-08-07T07:37:11.471+0000] {taskinstance.py:1323} INFO - Marking task as FAILED. dag_id=update_coupang, task_id=update_coupang, execution_date=20240806T080000, start_date=20240807T073711, end_date=20240807T073711
[2024-08-07T07:37:11.482+0000] {standard_task_runner.py:105} ERROR - Failed to execute job 12 for task update_coupang ([Errno 2] No such file or directory: '/data/shopai/dags/hatchery-shopai-v2-model/hatchery_extract_model/utils/mongo.yaml'; 32888)
[2024-08-07T07:37:11.513+0000] {local_task_job.py:208} INFO - Task exited with return code 1
[2024-08-07T07:37:11.566+0000] {taskinstance.py:2578} INFO - 0 downstream tasks scheduled from follow-on schedule check
[2024-08-07T09:01:20.970+0000] {local_task_job_runner.py:120} INFO - ::group::Pre task execution logs
[2024-08-07T09:01:20.993+0000] {taskinstance.py:2073} INFO - Dependencies all met for dep_context=non-requeueable deps ti=<TaskInstance: update_coupang.update_coupang scheduled__2024-08-06T08:00:00+00:00 [queued]>
[2024-08-07T09:01:21.001+0000] {taskinstance.py:2073} INFO - Dependencies all met for dep_context=requeueable deps ti=<TaskInstance: update_coupang.update_coupang scheduled__2024-08-06T08:00:00+00:00 [queued]>
[2024-08-07T09:01:21.002+0000] {taskinstance.py:2303} INFO - Starting attempt 1 of 1
[2024-08-07T09:01:21.015+0000] {taskinstance.py:2327} INFO - Executing <Task(PythonOperator): update_coupang> on 2024-08-06 08:00:00+00:00
[2024-08-07T09:01:21.022+0000] {standard_task_runner.py:63} INFO - Started process 112 to run task
[2024-08-07T09:01:21.025+0000] {standard_task_runner.py:90} INFO - Running: ['***', 'tasks', 'run', 'update_coupang', 'update_coupang', 'scheduled__2024-08-06T08:00:00+00:00', '--job-id', '14', '--raw', '--subdir', 'DAGS_FOLDER/coupang_batch.py', '--cfg-path', '/tmp/tmpjozcwci8']
[2024-08-07T09:01:21.027+0000] {standard_task_runner.py:91} INFO - Job 14: Subtask update_coupang
[2024-08-07T09:01:21.065+0000] {task_command.py:426} INFO - Running <TaskInstance: update_coupang.update_coupang scheduled__2024-08-06T08:00:00+00:00 [running]> on host 36f576e8f7f1
[2024-08-07T09:01:21.137+0000] {taskinstance.py:2644} INFO - Exporting env vars: AIRFLOW_CTX_DAG_OWNER='zzioni' AIRFLOW_CTX_DAG_ID='update_coupang' AIRFLOW_CTX_TASK_ID='update_coupang' AIRFLOW_CTX_EXECUTION_DATE='2024-08-06T08:00:00+00:00' AIRFLOW_CTX_TRY_NUMBER='1' AIRFLOW_CTX_DAG_RUN_ID='scheduled__2024-08-06T08:00:00+00:00'
[2024-08-07T09:01:21.138+0000] {taskinstance.py:430} INFO - ::endgroup::
[2024-08-07T09:01:21.139+0000] {taskinstance.py:441} INFO - ::group::Post task execution logs
[2024-08-07T09:01:21.139+0000] {taskinstance.py:2890} ERROR - Task failed with exception
Traceback (most recent call last):
  File "/home/airflow/.local/lib/python3.10/site-packages/airflow/models/taskinstance.py", line 465, in _execute_task
    result = _execute_callable(context=context, **execute_callable_kwargs)
  File "/home/airflow/.local/lib/python3.10/site-packages/airflow/models/taskinstance.py", line 432, in _execute_callable
    return execute_callable(context=context, **execute_callable_kwargs)
  File "/home/airflow/.local/lib/python3.10/site-packages/airflow/models/baseoperator.py", line 400, in wrapper
    return func(self, *args, **kwargs)
  File "/home/airflow/.local/lib/python3.10/site-packages/airflow/operators/python.py", line 235, in execute
    return_value = self.execute_callable()
  File "/home/airflow/.local/lib/python3.10/site-packages/airflow/operators/python.py", line 252, in execute_callable
    return self.python_callable(*self.op_args, **self.op_kwargs)
  File "/opt/airflow/dags/coupang_batch.py", line 98, in coupang_info_manual
    with open('/data/jw_vol/airflow/dags/mongo.yaml') as f:
FileNotFoundError: [Errno 2] No such file or directory: '/data/jw_vol/airflow/dags/mongo.yaml'
[2024-08-07T09:01:21.147+0000] {taskinstance.py:1205} INFO - Marking task as FAILED. dag_id=update_coupang, task_id=update_coupang, execution_date=20240806T080000, start_date=20240807T090120, end_date=20240807T090121
[2024-08-07T09:01:21.159+0000] {standard_task_runner.py:110} ERROR - Failed to execute job 14 for task update_coupang ([Errno 2] No such file or directory: '/data/jw_vol/airflow/dags/mongo.yaml'; 112)
[2024-08-07T09:01:21.197+0000] {local_task_job_runner.py:240} INFO - Task exited with return code 1
[2024-08-07T09:01:21.220+0000] {taskinstance.py:3482} INFO - 0 downstream tasks scheduled from follow-on schedule check
[2024-08-07T09:01:21.223+0000] {local_task_job_runner.py:222} INFO - ::endgroup::
