[2024-08-07T16:00:02.223+0000] {local_task_job_runner.py:120} INFO - ::group::Pre task execution logs
[2024-08-07T16:00:02.243+0000] {taskinstance.py:2073} INFO - Dependencies all met for dep_context=non-requeueable deps ti=<TaskInstance: update_coupang.update_coupang scheduled__2024-08-07T12:00:00+00:00 [queued]>
[2024-08-07T16:00:02.250+0000] {taskinstance.py:2073} INFO - Dependencies all met for dep_context=requeueable deps ti=<TaskInstance: update_coupang.update_coupang scheduled__2024-08-07T12:00:00+00:00 [queued]>
[2024-08-07T16:00:02.251+0000] {taskinstance.py:2303} INFO - Starting attempt 1 of 1
[2024-08-07T16:00:02.262+0000] {taskinstance.py:2327} INFO - Executing <Task(PythonOperator): update_coupang> on 2024-08-07 12:00:00+00:00
[2024-08-07T16:00:02.270+0000] {standard_task_runner.py:63} INFO - Started process 14399 to run task
[2024-08-07T16:00:02.272+0000] {standard_task_runner.py:90} INFO - Running: ['***', 'tasks', 'run', 'update_coupang', 'update_coupang', 'scheduled__2024-08-07T12:00:00+00:00', '--job-id', '37', '--raw', '--subdir', 'DAGS_FOLDER/coupang_batch.py', '--cfg-path', '/tmp/tmp44nfd58f']
[2024-08-07T16:00:02.274+0000] {standard_task_runner.py:91} INFO - Job 37: Subtask update_coupang
[2024-08-07T16:00:02.314+0000] {task_command.py:426} INFO - Running <TaskInstance: update_coupang.update_coupang scheduled__2024-08-07T12:00:00+00:00 [running]> on host 36f576e8f7f1
[2024-08-07T16:00:02.382+0000] {taskinstance.py:2644} INFO - Exporting env vars: AIRFLOW_CTX_DAG_OWNER='zzioni' AIRFLOW_CTX_DAG_ID='update_coupang' AIRFLOW_CTX_TASK_ID='update_coupang' AIRFLOW_CTX_EXECUTION_DATE='2024-08-07T12:00:00+00:00' AIRFLOW_CTX_TRY_NUMBER='1' AIRFLOW_CTX_DAG_RUN_ID='scheduled__2024-08-07T12:00:00+00:00'
[2024-08-07T16:00:02.384+0000] {taskinstance.py:430} INFO - ::endgroup::
[2024-08-07T16:00:02.384+0000] {taskinstance.py:441} INFO - ::group::Post task execution logs
[2024-08-07T16:00:02.384+0000] {taskinstance.py:2890} ERROR - Task failed with exception
Traceback (most recent call last):
  File "/home/airflow/.local/lib/python3.10/site-packages/airflow/models/taskinstance.py", line 465, in _execute_task
    result = _execute_callable(context=context, **execute_callable_kwargs)
  File "/home/airflow/.local/lib/python3.10/site-packages/airflow/models/taskinstance.py", line 432, in _execute_callable
    return execute_callable(context=context, **execute_callable_kwargs)
  File "/home/airflow/.local/lib/python3.10/site-packages/airflow/models/baseoperator.py", line 400, in wrapper
    return func(self, *args, **kwargs)
  File "/home/airflow/.local/lib/python3.10/site-packages/airflow/operators/python.py", line 235, in execute
    return_value = self.execute_callable()
  File "/home/airflow/.local/lib/python3.10/site-packages/airflow/operators/python.py", line 252, in execute_callable
    return self.python_callable(*self.op_args, **self.op_kwargs)
  File "/opt/airflow/dags/coupang_batch.py", line 98, in coupang_info_manual
    with open('/data/jw_vol/airflow/dags/mongo.yaml') as f:
FileNotFoundError: [Errno 2] No such file or directory: '/data/jw_vol/airflow/dags/mongo.yaml'
[2024-08-07T16:00:02.391+0000] {taskinstance.py:1205} INFO - Marking task as FAILED. dag_id=update_coupang, task_id=update_coupang, execution_date=20240807T120000, start_date=20240807T160002, end_date=20240807T160002
[2024-08-07T16:00:02.401+0000] {standard_task_runner.py:110} ERROR - Failed to execute job 37 for task update_coupang ([Errno 2] No such file or directory: '/data/jw_vol/airflow/dags/mongo.yaml'; 14399)
[2024-08-07T16:00:02.444+0000] {local_task_job_runner.py:240} INFO - Task exited with return code 1
[2024-08-07T16:00:02.465+0000] {taskinstance.py:3482} INFO - 0 downstream tasks scheduled from follow-on schedule check
[2024-08-07T16:00:02.468+0000] {local_task_job_runner.py:222} INFO - ::endgroup::
