[2024-08-07T07:37:11.563+0000] {taskinstance.py:1083} INFO - Dependencies all met for <TaskInstance: update_coupang.update_coupang scheduled__2024-08-06T16:00:00+00:00 [queued]>
[2024-08-07T07:37:11.572+0000] {taskinstance.py:1083} INFO - Dependencies all met for <TaskInstance: update_coupang.update_coupang scheduled__2024-08-06T16:00:00+00:00 [queued]>
[2024-08-07T07:37:11.572+0000] {taskinstance.py:1279} INFO - 
--------------------------------------------------------------------------------
[2024-08-07T07:37:11.572+0000] {taskinstance.py:1280} INFO - Starting attempt 1 of 1
[2024-08-07T07:37:11.572+0000] {taskinstance.py:1281} INFO - 
--------------------------------------------------------------------------------
[2024-08-07T07:37:11.585+0000] {taskinstance.py:1300} INFO - Executing <Task(PythonOperator): update_coupang> on 2024-08-06 16:00:00+00:00
[2024-08-07T07:37:11.592+0000] {standard_task_runner.py:55} INFO - Started process 32892 to run task
[2024-08-07T07:37:11.595+0000] {standard_task_runner.py:82} INFO - Running: ['***', 'tasks', 'run', 'update_coupang', 'update_coupang', 'scheduled__2024-08-06T16:00:00+00:00', '--job-id', '14', '--raw', '--subdir', 'DAGS_FOLDER/coupang_batch.py', '--cfg-path', '/tmp/tmposq2g8ot']
[2024-08-07T07:37:11.596+0000] {standard_task_runner.py:83} INFO - Job 14: Subtask update_coupang
[2024-08-07T07:37:11.648+0000] {task_command.py:388} INFO - Running <TaskInstance: update_coupang.update_coupang scheduled__2024-08-06T16:00:00+00:00 [running]> on host df52d8e27975
[2024-08-07T07:37:11.706+0000] {taskinstance.py:1509} INFO - Exporting the following env vars:
AIRFLOW_CTX_DAG_OWNER=zzioni
AIRFLOW_CTX_DAG_ID=update_coupang
AIRFLOW_CTX_TASK_ID=update_coupang
AIRFLOW_CTX_EXECUTION_DATE=2024-08-06T16:00:00+00:00
AIRFLOW_CTX_TRY_NUMBER=1
AIRFLOW_CTX_DAG_RUN_ID=scheduled__2024-08-06T16:00:00+00:00
[2024-08-07T07:37:11.707+0000] {taskinstance.py:1768} ERROR - Task failed with exception
Traceback (most recent call last):
  File "/home/airflow/.local/lib/python3.7/site-packages/airflow/operators/python.py", line 175, in execute
    return_value = self.execute_callable()
  File "/home/airflow/.local/lib/python3.7/site-packages/airflow/operators/python.py", line 192, in execute_callable
    return self.python_callable(*self.op_args, **self.op_kwargs)
  File "/opt/airflow/dags/coupang_batch.py", line 99, in coupang_info_manual
    with open('/data/shopai/dags/hatchery-shopai-v2-model/hatchery_extract_model/utils/mongo.yaml') as f:
FileNotFoundError: [Errno 2] No such file or directory: '/data/shopai/dags/hatchery-shopai-v2-model/hatchery_extract_model/utils/mongo.yaml'
[2024-08-07T07:37:11.714+0000] {taskinstance.py:1323} INFO - Marking task as FAILED. dag_id=update_coupang, task_id=update_coupang, execution_date=20240806T160000, start_date=20240807T073711, end_date=20240807T073711
[2024-08-07T07:37:11.723+0000] {standard_task_runner.py:105} ERROR - Failed to execute job 14 for task update_coupang ([Errno 2] No such file or directory: '/data/shopai/dags/hatchery-shopai-v2-model/hatchery_extract_model/utils/mongo.yaml'; 32892)
[2024-08-07T07:37:11.766+0000] {local_task_job.py:208} INFO - Task exited with return code 1
[2024-08-07T07:37:11.823+0000] {taskinstance.py:2578} INFO - 0 downstream tasks scheduled from follow-on schedule check
[2024-08-07T09:01:21.353+0000] {local_task_job_runner.py:120} INFO - ::group::Pre task execution logs
[2024-08-07T09:01:21.376+0000] {taskinstance.py:2073} INFO - Dependencies all met for dep_context=non-requeueable deps ti=<TaskInstance: update_coupang.update_coupang scheduled__2024-08-06T16:00:00+00:00 [queued]>
[2024-08-07T09:01:21.385+0000] {taskinstance.py:2073} INFO - Dependencies all met for dep_context=requeueable deps ti=<TaskInstance: update_coupang.update_coupang scheduled__2024-08-06T16:00:00+00:00 [queued]>
[2024-08-07T09:01:21.386+0000] {taskinstance.py:2303} INFO - Starting attempt 1 of 1
[2024-08-07T09:01:21.401+0000] {taskinstance.py:2327} INFO - Executing <Task(PythonOperator): update_coupang> on 2024-08-06 16:00:00+00:00
[2024-08-07T09:01:21.409+0000] {standard_task_runner.py:63} INFO - Started process 140 to run task
[2024-08-07T09:01:21.412+0000] {standard_task_runner.py:90} INFO - Running: ['***', 'tasks', 'run', 'update_coupang', 'update_coupang', 'scheduled__2024-08-06T16:00:00+00:00', '--job-id', '18', '--raw', '--subdir', 'DAGS_FOLDER/coupang_batch.py', '--cfg-path', '/tmp/tmpgw4bgxz0']
[2024-08-07T09:01:21.413+0000] {standard_task_runner.py:91} INFO - Job 18: Subtask update_coupang
[2024-08-07T09:01:21.457+0000] {task_command.py:426} INFO - Running <TaskInstance: update_coupang.update_coupang scheduled__2024-08-06T16:00:00+00:00 [running]> on host 36f576e8f7f1
[2024-08-07T09:01:21.534+0000] {taskinstance.py:2644} INFO - Exporting env vars: AIRFLOW_CTX_DAG_OWNER='zzioni' AIRFLOW_CTX_DAG_ID='update_coupang' AIRFLOW_CTX_TASK_ID='update_coupang' AIRFLOW_CTX_EXECUTION_DATE='2024-08-06T16:00:00+00:00' AIRFLOW_CTX_TRY_NUMBER='1' AIRFLOW_CTX_DAG_RUN_ID='scheduled__2024-08-06T16:00:00+00:00'
[2024-08-07T09:01:21.535+0000] {taskinstance.py:430} INFO - ::endgroup::
[2024-08-07T09:01:21.536+0000] {taskinstance.py:441} INFO - ::group::Post task execution logs
[2024-08-07T09:01:21.536+0000] {taskinstance.py:2890} ERROR - Task failed with exception
Traceback (most recent call last):
  File "/home/airflow/.local/lib/python3.10/site-packages/airflow/models/taskinstance.py", line 465, in _execute_task
    result = _execute_callable(context=context, **execute_callable_kwargs)
  File "/home/airflow/.local/lib/python3.10/site-packages/airflow/models/taskinstance.py", line 432, in _execute_callable
    return execute_callable(context=context, **execute_callable_kwargs)
  File "/home/airflow/.local/lib/python3.10/site-packages/airflow/models/baseoperator.py", line 400, in wrapper
    return func(self, *args, **kwargs)
  File "/home/airflow/.local/lib/python3.10/site-packages/airflow/operators/python.py", line 235, in execute
    return_value = self.execute_callable()
  File "/home/airflow/.local/lib/python3.10/site-packages/airflow/operators/python.py", line 252, in execute_callable
    return self.python_callable(*self.op_args, **self.op_kwargs)
  File "/opt/airflow/dags/coupang_batch.py", line 98, in coupang_info_manual
    with open('/data/jw_vol/airflow/dags/mongo.yaml') as f:
FileNotFoundError: [Errno 2] No such file or directory: '/data/jw_vol/airflow/dags/mongo.yaml'
[2024-08-07T09:01:21.544+0000] {taskinstance.py:1205} INFO - Marking task as FAILED. dag_id=update_coupang, task_id=update_coupang, execution_date=20240806T160000, start_date=20240807T090121, end_date=20240807T090121
[2024-08-07T09:01:21.556+0000] {standard_task_runner.py:110} ERROR - Failed to execute job 18 for task update_coupang ([Errno 2] No such file or directory: '/data/jw_vol/airflow/dags/mongo.yaml'; 140)
[2024-08-07T09:01:21.583+0000] {local_task_job_runner.py:240} INFO - Task exited with return code 1
[2024-08-07T09:01:21.625+0000] {taskinstance.py:3482} INFO - 0 downstream tasks scheduled from follow-on schedule check
[2024-08-07T09:01:21.629+0000] {local_task_job_runner.py:222} INFO - ::endgroup::
